Traceback (most recent call last):
  File "/usr/share/miniconda/lib/python3.7/site-packages/jupyter_cache/executors/utils.py", line 56, in single_nb_execution
    record_timing=False,
  File "/usr/share/miniconda/lib/python3.7/site-packages/nbclient/client.py", line 1087, in execute
    return NotebookClient(nb=nb, resources=resources, km=km, **kwargs).execute()
  File "/usr/share/miniconda/lib/python3.7/site-packages/nbclient/util.py", line 74, in wrapped
    return just_run(coro(*args, **kwargs))
  File "/usr/share/miniconda/lib/python3.7/site-packages/nbclient/util.py", line 53, in just_run
    return loop.run_until_complete(coro)
  File "/usr/share/miniconda/lib/python3.7/asyncio/base_events.py", line 587, in run_until_complete
    return future.result()
  File "/usr/share/miniconda/lib/python3.7/site-packages/nbclient/client.py", line 541, in async_execute
    cell, index, execution_count=self.code_cells_executed + 1
  File "/usr/share/miniconda/lib/python3.7/site-packages/nbclient/client.py", line 832, in async_execute_cell
    self._check_raise_for_error(cell, exec_reply)
  File "/usr/share/miniconda/lib/python3.7/site-packages/nbclient/client.py", line 740, in _check_raise_for_error
    raise CellExecutionError.from_cell_and_msg(cell, exec_reply['content'])
nbclient.exceptions.CellExecutionError: An error occurred while executing the following cell:
------------------
ui = OutputUI(expdir='../synthetic/data/Results_step')
ui.load_data()
ui.interface
------------------

[0;31m---------------------------------------------------------------------------[0m
[0;31mFileNotFoundError[0m                         Traceback (most recent call last)
[0;32m<ipython-input-2-d80b0e06cc62>[0m in [0;36m<module>[0;34m[0m
[1;32m      1[0m [0mui[0m [0;34m=[0m [0mOutputUI[0m[0;34m([0m[0mexpdir[0m[0;34m=[0m[0;34m'../synthetic/data/Results_step'[0m[0;34m)[0m[0;34m[0m[0;34m[0m[0m
[0;32m----> 2[0;31m [0mui[0m[0;34m.[0m[0mload_data[0m[0;34m([0m[0;34m)[0m[0;34m[0m[0;34m[0m[0m
[0m[1;32m      3[0m [0mui[0m[0;34m.[0m[0minterface[0m[0;34m[0m[0;34m[0m[0m

[0;32m/usr/share/miniconda/lib/python3.7/site-packages/morphodynamics/plots/ui_outputs.py[0m in [0;36mload_data[0;34m(self, b)[0m
[1;32m     68[0m [0;34m[0m[0m
[1;32m     69[0m         self.param, self.res, self.data = load_alldata(
[0;32m---> 70[0;31m             [0mself[0m[0;34m.[0m[0mexpdir[0m[0;34m,[0m [0mload_results[0m[0;34m=[0m[0;32mTrue[0m[0;34m[0m[0;34m[0m[0m
[0m[1;32m     71[0m         )
[1;32m     72[0m         [0mself[0m[0;34m.[0m[0mcreate_ui[0m[0;34m([0m[0;34m)[0m[0;34m[0m[0;34m[0m[0m

[0;32m/usr/share/miniconda/lib/python3.7/site-packages/morphodynamics/utils.py[0m in [0;36mload_alldata[0;34m(folder_path, load_results, param)[0m
[1;32m     40[0m [0;34m[0m[0m
[1;32m     41[0m         [0mparam[0m [0;34m=[0m [0mParam[0m[0;34m([0m[0;34m)[0m[0;34m[0m[0;34m[0m[0m
[0;32m---> 42[0;31m         [0;32mwith[0m [0mopen[0m[0;34m([0m[0mfolder_path[0m[0;34m.[0m[0mjoinpath[0m[0;34m([0m[0;34m"Parameters.yml"[0m[0;34m)[0m[0;34m)[0m [0;32mas[0m [0mfile[0m[0;34m:[0m[0;34m[0m[0;34m[0m[0m
[0m[1;32m     43[0m             [0mdocuments[0m [0;34m=[0m [0myaml[0m[0;34m.[0m[0mfull_load[0m[0;34m([0m[0mfile[0m[0;34m)[0m[0;34m[0m[0;34m[0m[0m
[1;32m     44[0m         [0;32mfor[0m [0mk[0m [0;32min[0m [0mdocuments[0m[0;34m.[0m[0mkeys[0m[0;34m([0m[0;34m)[0m[0;34m:[0m[0;34m[0m[0;34m[0m[0m

[0;31mFileNotFoundError[0m: [Errno 2] No such file or directory: '../synthetic/data/Results_step/Parameters.yml'
FileNotFoundError: [Errno 2] No such file or directory: '../synthetic/data/Results_step/Parameters.yml'

